Traceback (most recent call last):
  File "C:\Users\danie\miniconda3\envs\jupyterbook\lib\site-packages\jupyter_cache\executors\utils.py", line 58, in single_nb_execution
    executenb(
  File "C:\Users\danie\miniconda3\envs\jupyterbook\lib\site-packages\nbclient\client.py", line 1204, in execute
    return NotebookClient(nb=nb, resources=resources, km=km, **kwargs).execute()
  File "C:\Users\danie\miniconda3\envs\jupyterbook\lib\site-packages\nbclient\util.py", line 84, in wrapped
    return just_run(coro(*args, **kwargs))
  File "C:\Users\danie\miniconda3\envs\jupyterbook\lib\site-packages\nbclient\util.py", line 62, in just_run
    return loop.run_until_complete(coro)
  File "C:\Users\danie\miniconda3\envs\jupyterbook\lib\asyncio\base_events.py", line 647, in run_until_complete
    return future.result()
  File "C:\Users\danie\miniconda3\envs\jupyterbook\lib\site-packages\nbclient\client.py", line 663, in async_execute
    await self.async_execute_cell(
  File "C:\Users\danie\miniconda3\envs\jupyterbook\lib\site-packages\nbclient\client.py", line 965, in async_execute_cell
    await self._check_raise_for_error(cell, cell_index, exec_reply)
  File "C:\Users\danie\miniconda3\envs\jupyterbook\lib\site-packages\nbclient\client.py", line 862, in _check_raise_for_error
    raise CellExecutionError.from_cell_and_msg(cell, exec_reply_content)
nbclient.exceptions.CellExecutionError: An error occurred while executing the following cell:
------------------
CO2_elnino_df = pd.read_csv('CO2_merge_elnino_lanina.csv')


sns.lmplot(data=CO2_elnino_df, x='value', y='Classification')
plt.yticks([0, 1, 2], ['La Nina', 'Neither', 'El Nino'])
plt.xlabel('Value')
plt.ylabel('Classification')
plt.title('Linear Regression: Value vs. Classification')
plt.show()

sns.lmplot(data=CO2_elnino_df, x='year', y='Classification')
plt.yticks([0, 1, 2], ['La Nina', 'Neither', 'El Nino'])
plt.xlabel('year')
plt.ylabel('Classification')
plt.title('Linear Regression: Value vs. Classification')
plt.show()
------------------

[1;31m---------------------------------------------------------------------------[0m
[1;31mNameError[0m                                 Traceback (most recent call last)
Cell [1;32mIn[14], line 4[0m
[0;32m      1[0m CO2_elnino_df [38;5;241m=[39m pd[38;5;241m.[39mread_csv([38;5;124m'[39m[38;5;124mCO2_merge_elnino_lanina.csv[39m[38;5;124m'[39m)
[1;32m----> 4[0m [43msns[49m[38;5;241m.[39mlmplot(data[38;5;241m=[39mCO2_elnino_df, x[38;5;241m=[39m[38;5;124m'[39m[38;5;124mvalue[39m[38;5;124m'[39m, y[38;5;241m=[39m[38;5;124m'[39m[38;5;124mClassification[39m[38;5;124m'[39m)
[0;32m      5[0m plt[38;5;241m.[39myticks([[38;5;241m0[39m, [38;5;241m1[39m, [38;5;241m2[39m], [[38;5;124m'[39m[38;5;124mLa Nina[39m[38;5;124m'[39m, [38;5;124m'[39m[38;5;124mNeither[39m[38;5;124m'[39m, [38;5;124m'[39m[38;5;124mEl Nino[39m[38;5;124m'[39m])
[0;32m      6[0m plt[38;5;241m.[39mxlabel([38;5;124m'[39m[38;5;124mValue[39m[38;5;124m'[39m)

[1;31mNameError[0m: name 'sns' is not defined
NameError: name 'sns' is not defined

